Workbook

Sheet المرور
A2: وزارة الصحـة و الســـــكان
A3: الإدارة المركزية لجودة الرعاية الصحية
A4: الادارة العامة لمتابعة المديريات
A5: Hospital assessment standards 2025
A9: م | B9: المعيــــــار | C9: التقييم | D9: ملاحظات
A11: إشتراطات عامة:
A12: 1. النظام الصحي والخدمات:
A13: 1 | B13: لافتة بالخدمات المقدمة في المستشفى معلنة و محدثة و معتمدة.
A14: 2 | B14: لافتة رئيسية بأسعار الخدمات المقدمة معلنة و محدثة و معتمدة و لها مرجع.
A15: 3 | B15: لافتة فرعية بأسعار الخدمات المقدمة معلنة و محدثة و معتمدة و لها مرجع:  المعمل  الأشعة  الأسنان  أماكن أخرى
A16: 4 | B16: لافتة موضح بها توزيع وتقسيمات وحدات المبنى الداخلية بالتفصيل كل طابق على حدة .
A17: 2. القيادة والإدارة:
A18: 5 | B18: يوجد هيكل تنظيمي بالمسمى الوظيفى و الأسماء معلن و محدث و معتمد.
A19: 6 | B19: يوجد توصيف وظيفي لجميع العاملين و جميع المسميات الوظيفية بالمستشفى.
A20: 7 | B20: جميع العاملين على علم و دراية تامة بالتوصيف الوظيفي .
A21: 8 | B21: نسخة من الخطة الإستراتيجية العامة للمستشفى طبقاً لإستراتيجية الصحة.
A22: 9 | B22: نسخة من خطة العمل التشغيلية .
A23: 3. تنظيم العمل :
A24: 10 | B24: تواجد جداول عمل تنظيمية على مدار 24 ساعة لجميع العاملين بجميع أقسام المستشفى.
A25: 11 | B25: تواجد العاملون طبقا لجداول العمل التنظيمية بكل قسم.
A26: 12 | B26: يوجد رئيس لكل وحدة / قسم له مهام ومسئوليات محددة ( أمر تكليف موثق و معتمد).
A27: 13 | B27: يلتزم جميع العاملين بالزى الخاص بهم .
A28: 14 | B28: يلتزم جميع العاملين بوضع بادج تعريف موضح فيه : الإسم والقسم والصورة
A29: 15 | B29: يوجد مواصفات دخول و خروج معتمدة و متاحة للفريق الطبى لكل من :  العناية المركزة  وحدة الأطفال المبتسرين  وحدة الغسيل الكلوى  وحدة الحروق إن وُجدت.
A30: 16 | B30: وثيقة حقوق و واجبات المرضي واضحة ومعلنة و محدثة.
A31: 17 | B31: ملصقات منع التدخين معلنة و مطبقة بجميع الأماكن بالمستشفى.
A32: 4. البنية التحتية العامة بالمستشفى :
A33: 18 | B33: حجرات المنشأة الطبية جيدة التهوية والإضاءة
A34: 19 | B34: المنشأة مزودة بوسائل تغذيتها بالمياه النقية بصفة مستمرة
A35: 20 | B35: المنشأة مزودة بوسائل الصرف الصحى المناسبة و السليمة
A36: 21 | B36: تزود المنشأة بالوسائل والأدوات الصحية اللازمة للتخلص من القمامة والفضلات
A37: 22 | B37: تزود المنشأة بالأجهزة اللازمة لإطفاء الحريق
A38: 23 | B38: شهادة من إدارة الدفاع المدنى والحريق بتوفر الإشتراطات اللازمة للحماية من الحريق
A39: 24 | B39: طفاية لكل (30) متر مربع .
A40: 25 | B40: شهادة تداول المواد والنفايات الخطرة
A41: 26 | B41: ما يفيد التعاقد مع محرقة للنفايات الطبية
A42: 27 | B42: تزود كل غرفة من غرف المرضى بالمنشأة:  بأثاث سهل التنظيف لا يعوق التهوية والإضاءة  لاتقل المساحة المخصصة لكل سرير عن 9 متر  دورة مياه وحمام لكل عشرة أسرة على الأكثر فى حالة عدم تزويد الغرفة بدورة مياه مستقلة
A43: 28 | B43: توجد محطة تمريضية تسمح بمراقبة جميع المرضي :  أثاث لحفظ الملفات و السجلات ( المفتوحة) مؤمن.  أثاث لحفظ الأدوية  أثاث لحفظ المهمات و الآلات الطبية اللازمة للعمل التمريضي
A44: 29 | B44: توافر حوض مخصص لغسيل الأيدي به :  معنون بحوض غسيل الأيدى  مستلزمات غسيل الأيدى  ملصقات اللحظات الخمس و بوستر غسيل الأيدى ( و فى حالة عدم توافر حوض يوضع بوستر الدلك بالكحول).
... A49: 34 | B49: تدعم المستشفى حق المريض في التقدم بشكوى شفوية أو مكتوبة، موقعة أو غير موقعة:  توجد صناديق أو مكتب لتلقي الشكاوى.  وثيقة حقوق المريض تشمل هذا الحق.  توجد لجنة أو جهة لفحص الشكاوى.  يوجد سجل للشكاوى يتضمن إجراءات تصحيحية يتم إتخاذهافي الشكاوى.
...

Sheet الاجمالي
A1: المحافظة : الاسكندرية | E1: تواريخ التقييم :
A2: إسم المستشفي : أطفال الرمل | E2: إسم القائم بالتقييم : د/ آية المؤذن
A3: نوع المستشفي : تخصصي أطفال | E3: نتيجة التقييم : | F3: =E41 -> N/A
C5: م | D5: البــــند | E5: النسبة المئوية
C6: 1 | D6: الإشتراطات العامة | E6: =المرور!D74 -> N/A
C7: 2 | D7: السياسات و الإجراءات | E7: =المرور!D80 -> N/A
C8: 3 | D8: بروتوكولات العمل | E8: =المرور!D87 -> N/A
C9: 4 | D9: لجان المستشفى | E9: =المرور!D92 -> N/A
C10: 5 | D10: التسجيل الطبى | E10: =المرور!D103 -> N/A
C11: 6 | D11: السجلات | E11: =المرور!D107 -> N/A
C12: 7 | D12: الإقرارات | E12: =المرور!D111 -> N/A
C13: 8 | D13: العناية المركزة | E13: =المرور!D154 -> N/A
C14: 9 | D14: الطوارئ | E14: =المرور!D195 -> N/A
C15: 10 | D15: غرفة العقر | E15: =المرور!D212 -> N/A
C16: 11 | D16: العمليات | E16: =المرور!D261 -> N/A
C17: 12 | D17: الإفاقة | E17: =المرور!D278 -> N/A
C18: 13 | D18: وحدة المناظير | E18: =المرور!D299 -> N/A
C19: 14 | D19: وحدة القسطرة القلبية | E19: =المرور!D326 -> N/A
C20: 15 | D20: المبتسرين | E20: =المرور!D372 -> N/A
C21: 16 | D21: وحدة الغسيل الكلوي | E21: =المرور!D414 -> N/A
C22: 17 | D22: قسم الحروق | E22: =المرور!D431 -> N/A
C23: 18 | D23: العيادات الخارجية | E23: =المرور!D453 -> N/A
C24: 19 | D24: الأقسام الداخلية | E24: =المرور!D479 -> N/A
C25: 20 | D25: الأورام | E25: =المرور!D522 -> N/A
C26: 21 | D26: التشخيص عن بعد | E26: =المرور!D531 -> N/A
C27: 22 | D27: مواصفات غرف العزل | E27: =المرور!D540 -> N/A
C28: 23 | D28: الصيدلية | E28: =المرور!D556 -> N/A
C29: 24 | D29: المعمل | E29: =المرور!D633 -> N/A
C30: 25 | D30: الأشعة | E30: =المرور!D676 -> N/A
C31: 26 | D31: بنك الدم | E31: =المرور!D714 -> N/A
C32: 27 | D32: التعقيم | E32: =المرور!D750 -> N/A
C33: 28 | D33: وحدة غسيل المفروشات | E33: =المرور!D778 -> N/A
C34: 29 | D34: وحدة التغذية (المطبخ) | E34: =المرور!D804 -> N/A
C35: 30 | D35: غرفة حفظ الموتى | E35: =المرور!D821 -> N/A
C36: 31 | D36: غرفة النفايات | E36: =المرور!D834 -> N/A
C37: 32 | D37: الإنضباط و الإلتزام الإداري | E37: =المرور!D872 -> N/A
C38: 33 | D38: سكن الأطباء و التمريض | E38: =المرور!D879 -> N/A
C39: 34 | D39: تقييم و مراقبة أداء الخدمات الصحية المقدمة بالمنشأة | E39: =المرور!D896 -> N/A
C40: 35 | D40: العلاج الطبيعى | E40: =المرور!D935 -> N/A
D41: الإجمالي | E41: =IF(COUNT(المرور!C13:C934)=0,"N/A",SUM((المرور!C13:C934))/(COUNT((المرور!C13:C934))*2)) -> N/A
...

Sheet don,t delete or edit this sheet
A1: 0
A2: 1
A3: 2
A4: N/A
